Workbook

Sheet Cash & runway summary
A1: Cash & runway summary
A2: Runway · Main Scenario
A4: Variable / dimension | B4: Value
A5: Starting cash | B5: =0 -> 0
A6: Starting AWS credit | B6: =25 -> 25
A7: Steady-state monthly profit | B7: ='Model inputs'!O19-'Model inputs'!O9 -> 81.113
A8: Pre-revenue monthly burn | B8: ='Model inputs'!O9-'Model inputs'!O13 -> 18.557
A9: Pre-revenue runway (months) | B9: =IFERROR(('Cash & runway summary'!B5+'Cash & runway summary'!B6)/'Cash & runway summary'!B8,"") -> 1.3472005
A10: Runway (months) | B10: =IF(IF(IF(ISERROR('Cash & runway summary'!B7>=0),'Cash & runway summary'!B7>=0,IF('Cash & runway summary'!B7="","",'Cash & runway summary'!B7>=0))="",FALSE,IF(ISERROR('Cash & runway summary'!B7>=0),'Cash & runway summary'!B7>=0,IF('Cash & runway summary'!B7="","",'Cash & runway summary'!B7>=0))),"",('Cash & runway summary'!B5+'Cash & runway summary'!B6)/(0-'Cash & runway summary'!B7))
A11: Runway status | B11: =IF(IF(IF(ISERROR('Cash & runway summary'!B7>=0),'Cash & runway summary'!B7>=0,IF('Cash & runway summary'!B7="","",'Cash & runway summary'!B7>=0))="",FALSE,IF(ISERROR('Cash & runway summary'!B7>=0),'Cash & runway summary'!B7>=0,IF('Cash & runway summary'!B7="","",'Cash & runway summary'!B7>=0))),"Cash-flow positive: runway not limited by cash","Burning cash: see Runway (months)") -> Cash-flow positive: runway not limited by cash

Sheet Cash projection
A1: Cash projection
A2: Runway · Main Scenario
A4: Variable / dimension | B4: 2026-10 | C4: 2026-11 | D4: 2026-12 | E4: 2027-01 | F4: 2027-02 | G4: 2027-03 | H4: 2027-04 | I4: 2027-05 | J4: 2027-06 | K4: 2027-07 | L4: 2027-08 | M4: 2027-09
A5: Operating profit | B5: ='Model inputs'!C10-'Model inputs'!C18 -> 81.113 | C5: ='Model inputs'!D10-'Model inputs'!D18 -> 81.113 | D5: ='Model inputs'!E10-'Model inputs'!E18 -> 81.113 | E5: ='Model inputs'!F10-'Model inputs'!F18 -> 81.113 | F5: ='Model inputs'!G10-'Model inputs'!G18 -> 81.113 | G5: ='Model inputs'!H10-'Model inputs'!H18 -> 81.113 | H5: ='Model inputs'!I10-'Model inputs'!I18 -> 81.113 | I5: ='Model inputs'!J10-'Model inputs'!J18 -> 81.113 | ... M5: ='Model inputs'!N10-'Model inputs'!N18 -> 81.113
A6: AWS credit used | B6: =MIN('Model inputs'!B6,'Model inputs'!C11) -> 15.257 | C6: =MIN('Cash projection'!B7,'Model inputs'!D11) -> 9.743 | D6: =MIN('Cash projection'!C7,'Model inputs'!E11) -> 0 | E6: =MIN('Cash projection'!D7,'Model inputs'!F11) -> 0 | F6: =MIN('Cash projection'!E7,'Model inputs'!G11) -> 0 | G6: =MIN('Cash projection'!F7,'Model inputs'!H11) -> 0 | H6: =MIN('Cash projection'!G7,'Model inputs'!I11) -> 0 | I6: =MIN('Cash projection'!H7,'Model inputs'!J11) -> 0 | J6: =MIN('Cash projection'!I7,'Model inputs'!K11) -> 0 | ... M6: =MIN('Cash projection'!L7,'Model inputs'!N11) -> 0
A7: AWS credit remaining | B7: ='Model inputs'!B6-'Cash projection'!B6 -> 9.743 | C7: ='Cash projection'!B7-'Cash projection'!C6 -> 0 | D7: ='Cash projection'!C7-'Cash projection'!D6 -> 0 | E7: ='Cash projection'!D7-'Cash projection'!E6 -> 0 | F7: ='Cash projection'!E7-'Cash projection'!F6 -> 0 | G7: ='Cash projection'!F7-'Cash projection'!G6 -> 0 | H7: ='Cash projection'!G7-'Cash projection'!H6 -> 0 | I7: ='Cash projection'!H7-'Cash projection'!I6 -> 0 | J7: ='Cash projection'!I7-'Cash projection'!J6 -> 0 | ... M7: ='Cash projection'!L7-'Cash projection'!M6 -> 0
A8: Net cash flow | B8: ='Cash projection'!B5+'Cash projection'!B6 -> 96.37 | C8: ='Cash projection'!C5+'Cash projection'!C6 -> 90.856 | D8: ='Cash projection'!D5+'Cash projection'!D6 -> 81.113 | E8: ='Cash projection'!E5+'Cash projection'!E6 -> 81.113 | F8: ='Cash projection'!F5+'Cash projection'!F6 -> 81.113 | G8: ='Cash projection'!G5+'Cash projection'!G6 -> 81.113 | H8: ='Cash projection'!H5+'Cash projection'!H6 -> 81.113 | I8: ='Cash projection'!I5+'Cash projection'!I6 -> 81.113 | ... M8: ='Cash projection'!M5+'Cash projection'!M6 -> 81.113
A9: Cash balance | B9: ='Model inputs'!B8+'Cash projection'!B8 -> 96.37 | C9: ='Cash projection'!B9+'Cash projection'!C8 -> 187.226 | D9: ='Cash projection'!C9+'Cash projection'!D8 -> 268.339 | E9: ='Cash projection'!D9+'Cash projection'!E8 -> 349.452 | F9: ='Cash projection'!E9+'Cash projection'!F8 -> 430.565 | G9: ='Cash projection'!F9+'Cash projection'!G8 -> 511.678 | H9: ='Cash projection'!G9+'Cash projection'!H8 -> 592.791 | I9: ='Cash projection'!H9+'Cash projection'!I8 -> 673.904 | J9: ='Cash projection'!I9+'Cash projection'!J8 -> 755.017 | ... M9: ='Cash projection'!L9+'Cash projection'!M8 -> 998.356

Sheet Model inputs
A1: Model inputs
A2: Integration values are aggregated snapshots; raw source records are not included.
A4: Variables
A5: Variable / segment | B5: 2026-09 | C5: 2026-10 | D5: 2026-11 | E5: 2026-12 | F5: 2027-01 | G5: 2027-02 | H5: 2027-03 | I5: 2027-04 | J5: 2027-05 | K5: 2027-06 | L5: 2027-07 | M5: 2027-08 | N5: 2027-09 | O5: Value | P5: Value
A6: AWS credit remaining | B6: =IF('Cash & runway summary'!B6="","",'Cash & runway summary'!B6) -> 25 | C6: ='Model inputs'!B6-'Model inputs'!C7 -> 9.743 | D6: ='Model inputs'!C6-'Model inputs'!D7 -> 0 | E6: ='Model inputs'!D6-'Model inputs'!E7 -> 0 | F6: ='Model inputs'!E6-'Model inputs'!F7 -> 0 | G6: ='Model inputs'!F6-'Model inputs'!G7 -> 0 | H6: ='Model inputs'!G6-'Model inputs'!H7 -> 0 | I6: ='Model inputs'!H6-'Model inputs'!I7 -> 0 | J6: ='Model inputs'!I6-'Model inputs'!J7 -> 0 | ... N6: ='Model inputs'!M6-'Model inputs'!N7 -> 0
A7: AWS credit used | B7: 0 | C7: =MIN('Model inputs'!B6,'Model inputs'!C11) -> 15.257 | D7: =MIN('Model inputs'!C6,'Model inputs'!D11) -> 9.743 | E7: =MIN('Model inputs'!D6,'Model inputs'!E11) -> 0 | F7: =MIN('Model inputs'!E6,'Model inputs'!F11) -> 0 | G7: =MIN('Model inputs'!F6,'Model inputs'!G11) -> 0 | H7: =MIN('Model inputs'!G6,'Model inputs'!H11) -> 0 | I7: =MIN('Model inputs'!H6,'Model inputs'!I11) -> 0 | J7: =MIN('Model inputs'!I6,'Model inputs'!J11) -> 0 | ... N7: =MIN('Model inputs'!M6,'Model inputs'!N11) -> 0
A8: Cash balance | B8: =IF('Cash & runway summary'!B5="","",'Cash & runway summary'!B5) -> 0 | C8: ='Model inputs'!B8+'Model inputs'!C16 -> 96.37 | D8: ='Model inputs'!C8+'Model inputs'!D16 -> 187.226 | E8: ='Model inputs'!D8+'Model inputs'!E16 -> 268.339 | F8: ='Model inputs'!E8+'Model inputs'!F16 -> 349.452 | G8: ='Model inputs'!F8+'Model inputs'!G16 -> 430.565 | H8: ='Model inputs'!G8+'Model inputs'!H16 -> 511.678 | I8: ='Model inputs'!H8+'Model inputs'!I16 -> 592.791 | J8: ='Model inputs'!I8+'Model inputs'!J16 -> 673.904 | ... N8: ='Model inputs'!M8+'Model inputs'!N16 -> 998.356
A9: Fixed costs per month | O9: ='Model inputs'!O25+'Model inputs'!O31+'Model inputs'!O32 -> 15.257
A10: Gross profit | B10: 0 | C10: ='Model inputs'!C34-'Model inputs'!C24 -> 81.113 | D10: ='Model inputs'!D34-'Model inputs'!D24 -> 81.113 | E10: ='Model inputs'!E34-'Model inputs'!E24 -> 81.113 | F10: ='Model inputs'!F34-'Model inputs'!F24 -> 81.113 | G10: ='Model inputs'!G34-'Model inputs'!G24 -> 81.113 | H10: ='Model inputs'!H34-'Model inputs'!H24 -> 81.113 | I10: ='Model inputs'!I34-'Model inputs'!I24 -> 81.113 | J10: ='Model inputs'!J34-'Model inputs'!J24 -> 81.113 | ... N10: ='Model inputs'!N34-'Model inputs'!N24 -> 81.113
A11: Hosting | B11: 0 | C11: =IF('Model inputs'!O25="","",'Model inputs'!O25) -> 15.257 | D11: =IF('Model inputs'!O25="","",'Model inputs'!O25) -> 15.257 | E11: =IF('Model inputs'!O25="","",'Model inputs'!O25) -> 15.257 | F11: =IF('Model inputs'!O25="","",'Model inputs'!O25) -> 15.257 | G11: =IF('Model inputs'!O25="","",'Model inputs'!O25) -> 15.257 | H11: =IF('Model inputs'!O25="","",'Model inputs'!O25) -> 15.257 | I11: =IF('Model inputs'!O25="","",'Model inputs'!O25) -> 15.257 | J11: =IF('Model inputs'!O25="","",'Model inputs'!O25) -> 15.257 | K11: =IF('Model inputs'!O25="","",'Model inputs'!O25) -> 15.257 | L11: =IF('Model inputs'!O25="","",'Model inputs'!O25) -> 15.257 | M11: =IF('Model inputs'!O25="","",'Model inputs'!O25) -> 15.257 | N11: =IF('Model inputs'!O25="","",'Model inputs'!O25) -> 15.257
A12: Monthly contribution | O12: ='Model inputs'!O27*'Model inputs'!O20 -> 0
A13: Monthly contribution > Free planner | O13: ='Model inputs'!O28*'Model inputs'!O21 -> -3.3
A14: Monthly contribution > Freelancer Pro | O14: ='Model inputs'!O29*'Model inputs'!O22 -> 99.67
A15: Monthly contribution > Payout Desk | O15: ='Model inputs'!O30*'Model inputs'!O23 -> 0
A16: Net cash flow | B16: 0 | C16: ='Model inputs'!C17+'Model inputs'!C7 -> 96.37 | D16: ='Model inputs'!D17+'Model inputs'!D7 -> 90.856 | E16: ='Model inputs'!E17+'Model inputs'!E7 -> 81.113 | F16: ='Model inputs'!F17+'Model inputs'!F7 -> 81.113 | G16: ='Model inputs'!G17+'Model inputs'!G7 -> 81.113 | H16: ='Model inputs'!H17+'Model inputs'!H7 -> 81.113 | I16: ='Model inputs'!I17+'Model inputs'!I7 -> 81.113 | J16: ='Model inputs'!J17+'Model inputs'!J7 -> 81.113 | ... N16: ='Model inputs'!N17+'Model inputs'!N7 -> 81.113
A17: Operating profit | B17: 0 | C17: ='Model inputs'!C10-'Model inputs'!C18 -> 81.113 | D17: ='Model inputs'!D10-'Model inputs'!D18 -> 81.113 | E17: ='Model inputs'!E10-'Model inputs'!E18 -> 81.113 | F17: ='Model inputs'!F10-'Model inputs'!F18 -> 81.113 | G17: ='Model inputs'!G10-'Model inputs'!G18 -> 81.113 | H17: ='Model inputs'!H10-'Model inputs'!H18 -> 81.113 | I17: ='Model inputs'!I10-'Model inputs'!I18 -> 81.113 | J17: ='Model inputs'!J10-'Model inputs'!J18 -> 81.113 | ... N17: ='Model inputs'!N10-'Model inputs'!N18 -> 81.113
A18: Other operating expenses | B18: 0 | C18: =IF('Model inputs'!O32="","",'Model inputs'!O32) -> 0 | D18: =IF('Model inputs'!O32="","",'Model inputs'!O32) -> 0 | E18: =IF('Model inputs'!O32="","",'Model inputs'!O32) -> 0 | F18: =IF('Model inputs'!O32="","",'Model inputs'!O32) -> 0 | G18: =IF('Model inputs'!O32="","",'Model inputs'!O32) -> 0 | H18: =IF('Model inputs'!O32="","",'Model inputs'!O32) -> 0 | I18: =IF('Model inputs'!O32="","",'Model inputs'!O32) -> 0 | J18: =IF('Model inputs'!O32="","",'Model inputs'!O32) -> 0 | K18: =IF('Model inputs'!O32="","",'Model inputs'!O32) -> 0 | L18: =IF('Model inputs'!O32="","",'Model inputs'!O32) -> 0 | M18: =IF('Model inputs'!O32="","",'Model inputs'!O32) -> 0 | N18: =IF('Model inputs'!O32="","",'Model inputs'!O32) -> 0
A19: Total monthly contribution | O19: =SUM('Model inputs'!O13,'Model inputs'!O14,'Model inputs'!O15) -> 96.37
A20: Contribution per unit | O20: ='Model inputs'!O50-'Model inputs'!O40-'Model inputs'!O45 -> 0
A21: Contribution per unit > Free planner | O21: ='Model inputs'!O51-'Model inputs'!O41-'Model inputs'!O46 -> -0.0033
A22: Contribution per unit > Freelancer Pro | O22: ='Model inputs'!O52-'Model inputs'!O42-'Model inputs'!O47 -> 3.9868
A23: Contribution per unit > Payout Desk | O23: ='Model inputs'!O53-'Model inputs'!O43-'Model inputs'!O48 -> 1.9967
A24: Cost of revenue | B24: 0 | C24: ='Model inputs'!C39+'Model inputs'!C49+'Model inputs'!C11+'Model inputs'!C44 -> 18.887 | D24: ='Model inputs'!D39+'Model inputs'!D49+'Model inputs'!D11+'Model inputs'!D44 -> 18.887 | E24: ='Model inputs'!E39+'Model inputs'!E49+'Model inputs'!E11+'Model inputs'!E44 -> 18.887 | F24: ='Model inputs'!F39+'Model inputs'!F49+'Model inputs'!F11+'Model inputs'!F44 -> 18.887 | G24: ='Model inputs'!G39+'Model inputs'!G49+'Model inputs'!G11+'Model inputs'!G44 -> 18.887 | H24: ='Model inputs'!H39+'Model inputs'!H49+'Model inputs'!H11+'Model inputs'!H44 -> 18.887 | I24: ='Model inputs'!I39+'Model inputs'!I49+'Model inputs'!I11+'Model inputs'!I44 -> 18.887 | J24: ='Model inputs'!J39+'Model inputs'!J49+'Model inputs'!J11+'Model inputs'!J44 -> 18.887 | ... N24: ='Model inputs'!N39+'Model inputs'!N49+'Model inputs'!N11+'Model inputs'!N44 -> 18.887
A25: Hosting cost per month · Cash & runway summary | O25: ='Model inputs'!O35*'Model inputs'!O37 -> 15.257
A26: Hosting cost per month · Hosting | P26: ='Model inputs'!O35*'Model inputs'!O37 -> 15.257
A27: Monthly volume | O27: 0
A28: Monthly volume > Free planner | O28: =1000 -> 1000
A29: Monthly volume > Freelancer Pro | O29: =25 -> 25
A30: Monthly volume > Payout Desk | O30: =0 -> 0
A31: Observability cost per month | O31: =0 -> 0
A32: Other operating expenses per month · Cash & runway summary | O32: =0 -> 0
A33: Other operating expenses per month · Other operating expenses | P33: ='Model inputs'!O32 -> 0
A34: Revenue | B34: =SUM('Model inputs'!B55,'Model inputs'!B56,'Model inputs'!B57) -> 0 | C34: =SUM('Model inputs'!C55,'Model inputs'!C56,'Model inputs'!C57) -> 100 | D34: =SUM('Model inputs'!D55,'Model inputs'!D56,'Model inputs'!D57) -> 100 | E34: =SUM('Model inputs'!E55,'Model inputs'!E56,'Model inputs'!E57) -> 100 | F34: =SUM('Model inputs'!F55,'Model inputs'!F56,'Model inputs'!F57) -> 100 | G34: =SUM('Model inputs'!G55,'Model inputs'!G56,'Model inputs'!G57) -> 100 | H34: =SUM('Model inputs'!H55,'Model inputs'!H56,'Model inputs'!H57) -> 100 | I34: =SUM('Model inputs'!I55,'Model inputs'!I56,'Model inputs'!I57) -> 100 | ... N34: =SUM('Model inputs'!N55,'Model inputs'!N56,'Model inputs'!N57) -> 100
A35: Hosting hourly rate · Cash & runway summary | O35: =0.0209 -> 0.0209
A36: Hosting hourly rate · Hosting cost per month · Hosting | P36: ='Model inputs'!O35 -> 0.0209
A37: Hosting hours per month · Cash & runway summary | O37: =730 -> 730
A38: Hosting hours per month · Hosting cost per month · Hosting | P38: ='Model inputs'!O37 -> 730
A39: Inference cost | B39: =SUM('Model inputs'!B63,'Model inputs'!B64,'Model inputs'!B65) -> 0 | C39: =SUM('Model inputs'!C63,'Model inputs'!C64,'Model inputs'!C65) -> 3.63 | D39: =SUM('Model inputs'!D63,'Model inputs'!D64,'Model inputs'!D65) -> 3.63 | E39: =SUM('Model inputs'!E63,'Model inputs'!E64,'Model inputs'!E65) -> 3.63 | F39: =SUM('Model inputs'!F63,'Model inputs'!F64,'Model inputs'!F65) -> 3.63 | G39: =SUM('Model inputs'!G63,'Model inputs'!G64,'Model inputs'!G65) -> 3.63 | H39: =SUM('Model inputs'!H63,'Model inputs'!H64,'Model inputs'!H65) -> 3.63 | I39: =SUM('Model inputs'!I63,'Model inputs'!I64,'Model inputs'!I65) -> 3.63 | ... N39: =SUM('Model inputs'!N63,'Model inputs'!N64,'Model inputs'!N65) -> 3.63
A40: Inference cost per unit | O40: ='Model inputs'!O69*'Model inputs'!O66 -> 0
A41: Inference cost per unit > Free planner | O41: ='Model inputs'!O70*'Model inputs'!O66 -> 0.0033
...
